Workbook
Name Beg_Bal: #REF!
Name Cum_Int: #REF!
Name Data: #REF!
Name End_Bal: #REF!
Name Extra_Pay: #REF!
Name Full_Print: #REF!
Name Header_Row: #REF!
Name Int: #REF!
Name Interest_Rate: #REF!
Name Loan_Amount: #REF!
Name Loan_Start: #REF!
Name Loan_Years: #REF!
Name Num_Pmt_Per_Year: #REF!
Name Pay_Date: #REF!
Name Pay_Num: #REF!
Name Princ: #REF!
Name Sched_Pay: #REF!
Name Scheduled_Extra_Payments: #REF!
Name Scheduled_Interest_Rate: #REF!
Name Scheduled_Monthly_Payment: #REF!
Name Total_Interest: #REF!
Name Total_Pay: #REF!

Sheet Summary
C5: Myna Site
C6: Sl. No. | D6: Work Type | E6: Order Value | F6: Paid Amount | G6: Balance to pay
C7: 1 | D7: PO | E7: =+PO_Payments!M30 -> 5399325.2 | F7: =+PO_Payments!S30 -> 5345451 | G7: =+PO_Payments!T30 -> 53874.171
C8: 2 | D8: WO | E8: =+WO_Payments!M27 -> 23926473 | F8: =+WO_Payments!S27 -> 20799860 | G8: =+WO_Payments!T27 -> 3039292.5
C9: 3 | D9: Direct Payment | E9: =+Direct_Payments!J46 -> 2731924.5 | F9: =+Direct_Payments!P46 -> 2731926.9 | G9: =+Direct_Payments!Q46 -> -2.4052
C10: Grand Total | E10: =SUM(E7:E9) -> 32057722 | F10: =SUM(F7:F9) -> 28877238 | G10: =SUM(G7:G9) -> 3093164.3

Sheet PO_Payments
A1: Purchase Order Tracker - 2024 to 2025
N2: Payment Details | U2: Invoice Status | Y2: UTR Details
A3: S.No | B3: Submission Date | C3: Order Type | D3: Oder Ref No | E3: Order Date | F3: Budget No. | G3: Supplier | H3: Description | I3: Order Value | J3: Loading | K3: Freight | L3: Taxes | M3: Total Amount | N3: Advance 1 | O3: Advance 2 | P3: RA Bill 1 | Q3: RA Bill 2 | R3: Final Bill | S3: Total Paid | T3: Balance to pay | U3: Status | V3: Date | W3: Invoice No. | X3: Amount | Y3: Date | Z3: UTR No. | AA3: Remarks
A4: 1 | B4: 45757 | C4: PO | D4: AGN/PO/M-001/2025-26 | E4: 09.Nov.2025 | F4: 003 - 2024-25 | G4: Nitin wires and meshes Pvt Ltd. | H4: Supply of Nitin Trellis Stone 1205mm x 2410mm 5mm Thickness. | I4: 92000 | J4: 0 | K4: 0 | L4: =I4*18% -> 16560 | M4: =I4+J4+K4+L4 -> 108560 | N4: 108560 | S4: =N4+O4+P4+Q4+R4 -> 108560 | T4: =M4-S4 -> 0 | U4: Submitted | V4: 17.04.2025 | W4: 57603/2025-26 | X4: 108560 | AA4: Original Invoice submitted on 15.07.2025 - Mail
A5: 2 | B5: 45775 | C5: PO | D5: AGN/PO/M-002/2025-26 | E5: 45775 | F5: 014 - 2024-25 | G5: Somani Ispat Private Limited | H5: Supply of MS Pipes | I5: 65371.25 | J5: 0 | K5: 0 | L5: =I5*18% -> 11766.825 | M5: =I5+J5+K5+L5 -> 77138.075 | N5: 77138 | S5: =N5+O5+P5+Q5+R5 -> 77138 | T5: =M5-S5 -> 0.075 | U5: Not Submitted | AA5: 100% Advance as per client approval
A6: 3 | B6: 45775 | C6: PO | D6: AGN/PO/M-003/2025-26 | E6: 45775 | F6: 015 - 2024-25 | G6: Innovative Multitech Solutions | H6: Supply of MS Fabricated 300L Solat Tank | I6: 85000 | J6: 0 | K6: 0 | L6: =I6*18% -> 15300 | M6: =I6+J6+K6+L6 -> 100300 | N6: 100300 | S6: =N6+O6+P6+Q6+R6 -> 100300 | T6: =M6-S6 -> 0 | U6: Not Submitted | AA6: 100% Advance as per client approval
A7: 4 | B7: 45786 | C7: PO | D7: AGN/PO/M-027/2024-25 | E7: 45656 | F7: 224 - 2024-25 | G7: Zeo Concept Pvt Ltd | H7: Supply of furniture | I7: 1525424.6 | J7: 0 | K7: 0 | L7: =I7*18% -> 274576.42 | M7: =I7+L7 -> 1800001 | N7: 1122525 | O7: 677476 | S7: =N7+O7+P7+Q7+R7 -> 1800001 | T7: =M7-S7 -> -0.0074 | U7: Submitted | V7: 19.05.2025 | W7: oi-000580 | X7: 1154951 | AA7: Original Invoice submitted on 15.07.2025 - Mail
A8: 5 | B8: 09-05-2025 and 21.08.2025 | C8: PO | D8: AGN/PO/M-004/2025-26 | E8: 09.06.2025 | F8: 038 - 2025-26 | G8: Dastkari Designs Pvt Ltd | H8: Supply of furniture | I8: 737500 | J8: 0 | K8: 11000 | L8: =I8*18% -> 132750 | M8: =I8+L8+K8 -> 881250 | N8: 652687.5 | O8: 228562.5 | S8: =N8+O8+P8+Q8+R8 -> 881250 | T8: =M8-S8 -> 0 | U8: Submitted | V8: 30.08.2025 | W8: 149 | X8: 1211650 | AA8: Original invoice submitted - Invoice is mixing of two orders 004 and 006
A9: 6 | B9: 45840 | C9: PO | D9: AGN/PO/M-005/2025-26 | E9: 10.06.2025 | F9: 052 - 2025-26 | G9: Radha Krishna Granites & Tiles | H9: Supply of Polished Granite | I9: 34718.64 | J9: 0 | K9: 0 | L9: =I9*18% -> 6249.3552 | M9: =I9+L9 -> 40967.995 | R9: 40968 | S9: =N9+O9+P9+Q9+R9 -> 40968 | T9: =M9-S9 -> -0.0048 | U9: Submitted | V9: 10.06.2025 | W9: 13 | X9: 40968 | AA9: Original Invoice submitted with client approval
A10: 7 | B10: 09-05-2025 and 21.08.2025 | C10: PO | D10: AGN/PO/M-006/2025-26 | E10: 08.07.2025 | F10: 054 - 2025-26 | G10: Dastkari Designs Pvt Ltd | H10: Supply of Furniture | I10: 280000 | J10: 0 | K10: 0 | L10: =I10*18% -> 50400 | M10: =I10+L10 -> 330400 | N10: 247800 | R10: 82600 | S10: =N10+O10+P10+Q10+R10 -> 330400 | T10: =M10-S10 -> 0 | U10: Submitted | V10: 30.08.2025 | W10: 149 | X10: 1211650 | AA10: Original invoice submitted - Invoice is mixing of two orders 004 and 006
A11: 8 | B11: 21.08.2025 | C11: PO | D11: AGN/PO/M-016/2025-26 | E11: 01.08.2025 | F11: 075 - 2025-26 | G11: MVN Building Systems | H11: Supply of Steel and roofing sheets | I11: 161455.08 | J11: 0 | K11: 0 | L11: =I11*18% -> 29061.914 | M11: =I11+L11 -> 190516.99 | R11: 190517 | S11: =N11+O11+P11+Q11+R11 -> 190517 | T11: =M11-S11 -> -0.0056 | U11: Submitted | V11: 02.08.2025 | W11: MNV/25-26/106 | X11: 190517 | AA11: Original invoice submitted
A12: 9 | B12: 21.08.2025 | C12: PO | D12: AGN/PO/M-017/2025-26 | E12: 01.08.2025 | F12: 073 - 2025-26 | G12: Robo Gates India Pvt Ltd | H12: Sliding gate fabrication work | I12: 95546.61 | J12: 0 | K12: 0 | L12: =I12*18% -> 17198.39 | M12: =I12+L12 -> 112745 | R12: 112745 | S12: =N12+O12+P12+Q12+R12 -> 112745 | T12: =M12-S12 -> -0.00019999999 | U12: Submitted | V12: 21.08.2025 | W12: 25-2623 | X12: 112745 | AA12: Original invoice submitted
A13: 10 | B13: 21.08.2025 | C13: PO | D13: AGN/PO/M-018/2025-26 | E13: 01.08.2025 | F13: 074 - 2025-26 | G13: Raga Glass Emporium | H13: Supply and fixing of 12mm Glass | I13: 32120.33 | J13: 0 | K13: 0 | L13: =I13*18% -> 5781.6594 | M13: =I13+L13 -> 37901.989 | R13: 37902 | S13: =N13+O13+P13+Q13+R13 -> 37902 | T13: =M13-S13 -> -0.0106 | U13: Submitted | V13: 21.08.2025 | W13: 94 | X13: 31902 | AA13: Original invoice submitted
A14: 11 | B14: 29.08.2025 | C14: PO | D14: AGN/PO/M-020/2025-26 | E14: 29.08.2025 | F14: 076 - 2025-26 | G14: Mahavir Steel & Tubes | H14: Supply of Steel | I14: 71242.37 | J14: 0 | K14: 0 | L14: =I14*18% -> 12823.627 | M14: =I14+L14 -> 84065.997 | R14: 76818 | S14: =N14+O14+P14+Q14+R14 -> 76818 | T14: =M14-S14 -> 7247.9966 | U14: Submitted | V14: 30.08.2025 | W14: 1220 | X14: 76818 | AA14: Remainging balance received 7247.00 and Original invoice submitted - PO short closed
A15: 12 | B15: 45916 | C15: PO | D15: AGN/PO/M-023/2025-26 | E15: 16.09.2025 | F15: 077 - 2025-26 | G15: Aqualus water Solutions | H15: Supply of Geo-Textile and HDPE Sheets | I15: 29250 | J15: 0 | K15: 0 | L15: =I15*18% -> 5265 | M15: =I15+L15 -> 34515 | N15: 34515 | S15: =N15+O15+P15+Q15+R15 -> 34515 | T15: =M15-S15 -> 0 | U15: Not Submitted | AA15: 100% Advance as per client approval
A16: 13 | B16: 09.10.2025 | C16: PO | D16: AGN/PO/M-025/2025-26 | E16: 09.10.2025 | F16: 086 - 2025-26 | G16: BSA Steel Private Limited | H16: Supply of Steel | I16: 344067 | J16: 0 | K16: 0 | L16: =I16*18% -> 61932.06 | M16: =I16+L16 -> 405999.06 | R16: 413016 | S16: =N16+O16+P16+Q16+R16 -> 413016 | T16: =M16-S16 -> -7016.94 | U16: Submitted | V16: 10.10.2025 | W16: BSA/03441/2526 | X16: 413016 | AA16: Original invoice submitted - Qty.Excess as per the weigh so invoice value increased
A17: 14 | B17: 45944 | C17: PO | D17: AGN/PO/M-025/2025-26 | E17: 09.09.2025 | F17: 087 - 2025-26 | G17: Jain Metal | H17: Supply of CC Sheets and Steel | I17: 51035 | J17: 0 | K17: 0 | L17: =I17*18% -> 9186.3 | M17: =I17+L17 -> 60221.3 | N17: 60221 | S17: =N17+O17+P17+Q17+R17 -> 60221 | T17: =M17-S17 -> 0.3 | U17: Not Submitted | AA17: 100% Advance as per client approval
A18: 15 | B18: 45979 | C18: PO | D18: AGN/PO/M-030/2025-26 | E18: 45979 | F18: 096 - 2025-26 | G18: Jain Metal | H18: Supply of Steel | I18: 61494.91 | J18: 0 | K18: 0 | L18: =I18*18% -> 11069.084 | M18: =I18+L18 -> 72563.994 | N18: 72563.99 | S18: =N18+O18+P18+Q18+R18 -> 72563.99 | T18: =M18-S18 -> 0.0038 | U18: Submitted | V18: 18.11.2025 | W18: INV/25-26/463 | X18: 71520 | AA18: 100% Advance as per client approval
A19: 16 | B19: 45980 | C19: PO | D19: AGN/PO/M-031/2025-26 | E19: 45980 | F19: 097 - 2025-26 | G19: Deccan Wire Netting Works | H19: Supply of Chain-link mesh | I19: 62500 | J19: 0 | K19: 0 | L19: =I19*18% -> 11250 | M19: =I19+L19 -> 73750 | N19: 73750 | S19: =N19+O19+P19+Q19+R19 -> 73750 | T19: =M19-S19 -> 0 | U19: Not Submitted | AA19: 100% Advance as per client approval
A20: 17 | B20: 45987 | C20: PO | D20: AGN/PO/M-032/2025-26 | E20: 45987 | F20: 099 - 2025-26 | G20: Jain Metal | H20: Supply of Steel | I20: 160310 | J20: 0 | K20: 0 | L20: =I20*18% -> 28855.8 | M20: =I20+L20 -> 189165.8 | N20: 189166 | S20: =N20+O20+P20+Q20+R20 -> 189166 | T20: =M20-S20 -> -0.2 | U20: Not Submitted | AA20: 100% Advance as per client approval
A21: 18 | B21: 28-11-2025 and 05.01.2026 | C21: PO | D21: AGN/PO/M-033/2025-26 | E21: 45988 | F21: 0101 - 2025-26 | G21: Basant Florring Pvt Ltd | H21: Supply of Shot blasted Square Pavers | I21: 223250 | J21: 0 | K21: 0 | L21: =I21*18% -> 40185 | M21: =I21+L21 -> 263435 | N21: =M21*50% -> 131717.5 | O21: 131717.5 | S21: =N21+O21+P21+Q21+R21 -> 263435 | T21: =M21-S21 -> 0 | U21: Not Submitted | AA21: 50% Advance as per client approval. Balance 50% paid
A22: 19 | B22: 23-12-2025 and 20.01.2026 | C22: PO | D22: AGN/PO/M-038/2025-26 | E22: 46013 | F22: 0103 - 2025-26 | G22: Classic Reflective Pavers | H22: Supply of Grass Pavers | I22: 105600 | J22: 0 | K22: 0 | L22: =I22*18% -> 19008 | M22: =I22+L22 -> 124608 | N22: =M22*50% -> 62304 | O22: 62304 | S22: =N22+O22+P22+Q22+R22 -> 124608 | T22: =M22-S22 -> 0 | U22: Not Submitted | AA22: 50% Advance as per client approval & balance 50% paid as per clint approval
A23: 20 | B23: 46031 | C23: PO | D23: AGN/PO/M-033/2025-26 | E23: 45988 | F23: 0101 - 2025-26 | G23: Aditi Trans | H23: Transport charges for Shot blasted Square Pavers | I23: 52500 | J23: 0 | K23: 0 | M23: =I23+L23 -> 52500 | N23: 52500 | S23: =N23+O23+P23+Q23+R23 -> 52500 | T23: =M23-S23 -> 0 | U23: Not Submitted | AA23: 100% Advance as per client approval
A24: 21 | B24: 46042 | C24: PO | D24: AGN/PO/M-043/2025-26 | E24: 46042 | F24: 0114 - 2025-26 | G24: Srinika Traders | H24: Supply of Shera Pro Plain Boards | I24: 41003.38 | J24: 0 | K24: 0 | L24: =I24*18% -> 7380.6084 | M24: =I24+L24 -> 48383.988 | N24: 48384 | S24: =N24+O24+P24+Q24+R24 -> 48384 | T24: =M24-S24 -> -0.0116 | U24: Not Submitted | AA24: 100% Advance as per client approval
A25: 22 | B25: 46053 | C25: PO | D25: AGN/PO/M-042/2025-26 | E25: 46035 | F25: 0111 - 2025-26 | G25: Anjani Vishnu Allied Services Limited | H25: Supply of Tiles | I25: 76965.25 | J25: 0 | K25: 0 | L25: =I25*18% -> 13853.745 | M25: =I25+L25 -> 90818.995 | N25: 90819 | S25: =N25+O25+P25+Q25+R25 -> 90819 | T25: =M25-S25 -> -0.005 | U25: Not Submitted | AA25: 100% Advance as per client approval
A26: 23 | B26: 46056 | C26: PO | D26: AGN/PO/M-045/2025-26 | E26: 46056 | F26: 0117 - 2025-26 | G26: Jain Metal | H26: Supply of Steel | I26: 53111.01 | J26: 0 | K26: 0 | L26: =I26*18% -> 9559.9818 | M26: =I26+L26 -> 62670.992 | N26: 62671 | S26: =N26+O26+P26+Q26+R26 -> 62671 | T26: =M26-S26 -> -0.0082 | U26: Submitted | V26: 03.02.2026 | W26: INV/25-26/615 | X26: 61100 | AA26: 100% Advance as per client approval
A27: 24 | B27: 46058 | C27: PO | D27: AGN/PO/M-046/2025-26 | E27: 46058 | F27: 0120 - 2025-26 | G27: OSB Prefab Technologies | H27: Supply of Roof Panels with PPGI | I27: 90920.33 | J27: 0 | K27: 0 | L27: =I27*18% -> 16365.659 | M27: =I27+L27 -> 107285.99 | N27: 53643 | S27: =N27+O27+P27+Q27+R27 -> 53643 | T27: =M27-S27 -> 53642.989 | U27: Not Submitted | AA27: 50% Advance as per client approval
A28: 25 | B28: 46059 | C28: PO | D28: AGN/PO/M-047/2025-26 | E28: 46059 | F28: 0120 - 2025-26 | G28: Deccan Wire Netting Works | H28: Supply of Chain-link mesh | I28: 42000 | J28: 0 | K28: 0 | L28: =I28*18% -> 7560 | M28: =I28+L28 -> 49560 | N28: 49560 | S28: =N28+O28+P28+Q28+R28 -> 49560 | T28: =M28-S28 -> 0 | U28: Not Submitted | AA28: 100% Advance as per client approval
A30: Grand Total | M30: =SUM(M4:M29) -> 5399325.2 | N30: =SUM(N4:N29) -> 3290825 | O30: =SUM(O4:O29) -> 1100060 | P30: =SUM(P4:P29) -> 0 | Q30: =SUM(Q4:Q29) -> 0 | R30: =SUM(R4:R29) -> 954566 | S30: =SUM(S4:S29) -> 5345451 | T30: =SUM(T4:T29) -> 53874.171 | ... V30: =SUM(V4:V29) -> 0 | X30: =SUM(X4:X29) -> 4685397

Sheet WO_Payments
A1: Invoice Tracker Work Order - 2025 to 2026
N2: Payment Details | U2: Invoice Status | Y2: UTR Details
A3: S.No | B3: Date | C3: Order Type | D3: Oder Ref No | E3: Order Date | F3: Budget No. | G3: Supplier | H3: Description | I3: Order Value | J3: Loading | K3: Freight | L3: Taxes | M3: Total Amount | N3: Advance 1 | O3: Advance 2 | P3: RA Bill 1 | Q3: RA Bill 2 | R3: Final Bill | S3: Total Paid | T3: Balance to pay | U3: Status | V3: Date | W3: Invoice No. | X3: Amount | Y3: Date | Z3: UTR No. | AA3: Remarks
A4: 1 | B4: 45776 | C4: WO | D4: AGN/WO/M-001/2025-26 | E4: 45769 | F4: 003 - 2024-25 | G4: Robo Gates India Pvt Ltd | H4: MS Showing Gate size 18.5ftx7ft | I4: 100800 | J4: - | K4: - | L4: =I4*18% -> 18144 | M4: =I4+L4 -> 118944 | N4: =M4*75% -> 89208 | S4: =N4+O4+P4+Q4+R4 -> 89208 | T4: =M4-S4 -> 29736 | U4: Not Submitted | AA4: 75% Adavnec as per client approval
A5: 2 | B5: 45810 | C5: WO | D5: AGN/WO/M-046/2024-25 | E5: 45744 | F5: 277 - 2024-25 | G5: Jayadurga Furnishings Pvt Ltd | H5: Supply and fixing of curtains | I5: 625501 | J5: - | K5: - | L5: 80362.66 | M5: =I5+L5 -> 705863.66 | N5: 482351 | R5: 223513 | S5: =N5+O5+P5+Q5+R5 -> 705864 | T5: =M5-S5 -> -0.34 | U5: Submitted | V5: 29.03.2025, 29.03.2025, 02.04.2025, 04.04.2025, 04.04.2025, 08.04.2025, 21.04.2025, 22.04.2025 and 28.04.2025 | W5: SRV-24-25-624, SI-24-25-10714, SI-25-26-00051, SI-25-26-00108, SI-25-26-00116, SI-25-26-00203, SI-25-26-00487, SRV-25-26-83 and CS-25-26-342 | X5: 49,570.00, 2360.00, 35599.00, 166359.00, 17916.00, 28763.00, 363171.00, 24780.00 and 17346.00 | AA5: All original invoices submitted with client sign
A6: 3 | B6: 45820 | C6: WO | D6: AGN/WO/M-002/2025-26 | E6: 45778 | F6: 040 - 2024-25 | G6: Mallick & Co | H6: Plumbing Work | I6: 504806.41 | J6: - | K6: - | L6: =I6*18% -> 90865.154 | M6: =I6+L6 -> 595671.56 | R6: 595672 | S6: =N6+O6+P6+Q6+R6 -> 595672 | T6: =M6-S6 -> -0.4362 | U6: Submitted | V6: 12.05.2025 | W6: MC/25-26/013 | X6: 595672 | AA6: Final Bill - Original invoice submitted with Madam Approval
A7: 4 | B7: 45820 | C7: WO | D7: AGN/WO/M-003/2025-26 | E7: 45782 | F7: 041 - 2024-25 | G7: Vishal Prajapathi | H7: Labour charges for wooden Flooring polish work - Myna | I7: 110390 | J7: - | K7: - | M7: =I7+L7 -> 110390 | R7: 110390 | S7: =N7+O7+P7+Q7+R7 -> 110390 | T7: =M7-S7 -> 0 | U7: Submitted | AA7: Final Bill - Original non GST invoice submitted with Madam Approval
A8: 5 | B8: 45825 | C8: WO | D8: AGN/WO/M-007/2025-26 | E8: 45807 | F8: 045 - 2025-26 | G8: Mounika Construction | H8: Lake side CRS work | I8: 158250 | L8: =I8*18% -> 28485 | M8: =I8+L8 -> 186735 | R8: 186735 | S8: =N8+O8+P8+Q8+R8 -> 186735 | T8: =M8-S8 -> 0 | U8: Submitted | V8: 17.06.2025 | W8: mou17/06/2025/02 | X8: 186736 | AA8: All original invoices submitted with client sign
A9: 6 | B9: 45825 | C9: WO | D9: AGN/WO/M-008/2025-26 | E9: 45807 | F9: 046 - 2025-26 | G9: Mounika Construction | H9: Lake side Retaing wall work | I9: 1016495 | L9: =I9*18% -> 182969.1 | M9: =I9+L9 -> 1199464.1 | R9: 1199464.1 | S9: =N9+O9+P9+Q9+R9 -> 1199464.1 | T9: =M9-S9 -> 0 | U9: Submitted | V9: 17.06.2025 | W9: mou17/06/2025 | X9: 1199466 | AA9: All original invoices submitted with client sign
A10: 7 | B10: 45825 | C10: WO | D10: AGN/WO/M-009/2025-26 | E10: 45807 | F10: 047 - 2025-26 | G10: Mounika Construction | H10: Civil Work | I10: 168403.62 | L10: =I10*18% -> 30312.652 | M10: =I10+L10 -> 198716.27 | R10: 198716.27 | S10: =N10+O10+P10+Q10+R10 -> 198716.27 | T10: =M10-S10 -> 0.0016 | U10: Submitted | V10: 17.06.2025 | W10: mou17/06/2025/03 | X10: 198716 | AA10: All original invoices submitted with client sign
A11: 8 | B11: 45883 | C11: WO | D11: AGN/WO/M-014/2025-26 | E11: 45870 | F11: 068 - 2025-26 | G11: Little Twigs Studio | H11: Architectural Advisary Service charges | I11: 50000 | L11: =I11*18% -> 9000 | M11: =I11+L11 -> 59000 | R11: 59000 | S11: =N11+O11+P11+Q11+R11 -> 59000 | T11: =M11-S11 -> 0 | U11: Submitted | V11: 13.08.2025 | W11: 6 | X11: 59000 | AA11: All original invoices submitted
A12: 9 | B12: 45887 | C12: WO | D12: AGN/WO/M-016/2025-26 | E12: 45870 | F12: 071 - 2025-26 | G12: Mounika Construction | H12: Civil Work | I12: 946677.96 | L12: =I12*18% -> 170402.03 | M12: =I12+L12 -> 1117080 | R12: 1117080 | S12: =N12+O12+P12+Q12+R12 -> 1117080 | T12: =M12-S12 -> -0.0072000001 | U12: Submitted | V12: 45887 | W12: mou18/08/2025 | X12: 1117080 | AA12: Final Bill all original invoices submitted with client sign
A13: 10 | B13: 45887 | C13: WO | D13: AGN/WO/M-015/2025-26 | E13: 45870 | F13: 070 - 2025-26 | G13: Mounika Construction | H13: Civil Work | I13: 571605.93 | L13: =I13*18% -> 102889.07 | M13: =I13+L13 -> 674495 | R13: 674495 | S13: =N13+O13+P13+Q13+R13 -> 674495 | T13: =M13-S13 -> -0.0026 | U13: Submitted | V13: 45887 | W13: mou18/08/2025/01 | X13: 674495 | AA13: Final Bill all original invoices submitted with client sign
A14: 11 | B14: 45918 | C14: WO | D14: AGN/WO/M-009/2024-25 | E14: 45429 | F14: 039 - 2024-25 | G14: Go Infrastructures | H14: Supply and fixing of Glass Windows | I14: 1856776.3 | L14: =I14*18% -> 334219.73 | M14: =I14+L14 -> 2190996 | N14: 1533697.2 | O14: 438198.9 | R14: 131779.9 | S14: =N14+O14+P14+Q14+R14 -> 2103676 | T14: Short Closed WO | U14: Submitted | V14: 11.08.2024 | W14: GI/24-25/007 | X14: 2190996 | AA14: Final Bill all original invoices submitted with client sign - Credit note of 87320.00 also submitted
A15: 12 | B15: 45929 | C15: WO | D15: AGN/WO/M-019/2025-26 | E15: 45870 | F15: 080 - 2025-26 | G15: Mounika Construction | H15: Civil Work for Service Rooms and Main gate area | I15: 449947.94 | L15: =I15*18% -> 80990.629 | M15: =I15+L15 -> 530938.57 | R15: 530939 | S15: =N15+O15+P15+Q15+R15 -> 530939 | T15: =M15-S15 -> -0.4308 | U15: Submitted | V15: 25.09.2025 | W15: mou27/09/2025 | X15: 530939 | AA15: Final Bill all original invoices submitted with client sign
A16: 13 | B16: 29-09-2025 and 24.12.2025 | C16: WO | D16: AGN/WO/M-023/2025-26_Amended | E16: 25-09-2025 and 24.12.2025 | F16: 079 - 2025-26 | G16: Mounika Construction | H16: Civil Work for Dog Room and external works | I16: 2529413.5 | L16: =I16*18% -> 455294.44 | M16: =I16+L16 -> 2984708 | N16: 300000 | R16: 2684708 | S16: =N16+O16+P16+Q16+R16 -> 2984708 | T16: =M16-S16 -> -0.011 | U16: Submitted | V16: 24.12.2025 | W16: mou24/12/2025 | X16: 2984708 | AA16: Final Bill submitted with approval
A17: 14 | B17: 45929 | C17: WO | D17: AGN/WO/M-001/2024-25 | E17: 45750 | F17: 001 - 2024-25 | G17: Mounika Construction | H17: Civil Work | I17: 4737665.1 | L17: =I17*18% -> 852779.72 | M17: =I17+L17 -> 5590444.8 | N17: 4500000 | R17: 548471 | S17: =N17+O17+P17+Q17+R17 -> 5048471 | T17: =M17-S17 -> 541973.84 | U17: Submitted | V17: 25.09.2025 | W17: mou25/09/2025 | X17: 5048471 | AA17: Original Invoice submitted and WO short closed
A18: 15 | B18: 45929 | C18: WO | D18: AGN/WO/M-020/2025-26 | E18: 45902 | F18: 081 - 2025-26 | G18: M.N.V Building System | H18: Supply and fabrication of steel | I18: 87081 | L18: =I18*18% -> 15674.58 | M18: =I18+L18 -> 102755.58 | R18: 102756 | S18: =N18+O18+P18+Q18+R18 -> 102756 | T18: =M18-S18 -> -0.42 | U18: Submitted | V18: 29.09.2025 | W18: MNV/25-26/113 | X18: 102756 | AA18: Original Invoice submitted and WO short closed
A19: 16 | B19: 45973 | C19: WO | D19: AGN/WO/M-027/2025-26 | E19: 45972 | F19: 094 - 2025-26 | G19: Neptune Agri Solutions | H19: SITC of Manual Irrigation works | I19: 1376303 | L19: =29204.79+142597.3 -> 171802.09 | M19: =I19+L19 -> 1548105.1 | N19: =M19*20% -> 309621.02 | S19: =N19+O19+P19+Q19+R19 -> 309621.02 | T19: =M19-S19 -> 1238484.1 | U19: Not Submitted | AA19: 20% Adavnec as per client approval
A20: 17 | B20: 45974 | C20: WO | D20: AGN/WO/M-025/2025-26 | E20: 45962 | F20: 095 - 2025-26 | G20: Little Twigs Studio | H20: Architectural Advisary Service charges | I20: 100000 | L20: =I20*18% -> 18000 | M20: =I20+L20 -> 118000 | R20: 118000 | S20: =N20+O20+P20+Q20+R20 -> 118000 | T20: =M20-S20 -> 0 | U20: Submitted | V20: 08.11.2025 | W20: 7 | X20: 118000 | AA20: All original invoices submitted
A21: 18 | B21: 45985 | C21: WO | D21: AGN/WO/M-029/2025-26 | E21: 45985 | F21: 098 - 2025-26 | G21: Classic Flooring &Interiors Pvt Ltd | H21: Suuply and apply of Wooden Flooring | I21: 219626.27 | L21: =I21*18% -> 39532.729 | M21: =I21+L21 -> 259159 | N21: 259159 | S21: =N21+O21+P21+Q21+R21 -> 259159 | T21: =M21-S21 -> -0.0014 | U21: Not Submitted | AA21: 100% Adavnec as per client approval
A22: 19 | B22: 11/28/2025 and 19/02/2026 | C22: WO | D22: AGN/WO/M-029/2025-26 | E22: 45988 | F22: 0100 - 2025-26 | G22: GSRK Tiles and Granites | H22: Suuply and laying of Granite | I22: 1768250 | L22: =37400+183645 -> 221045 | M22: =I22+L22 -> 1989295 | N22: 599565 | R22: 160629.74 | S22: =N22+O22+P22+Q22+R22 -> 760194.74 | T22: =M22-S22 -> 1229100.3 | U22: Submitted | V22: 13.02.2026 | W22: GSRK-26-002 | X22: 760194.74 | AA22: 60% Adavnec on supply amount as per client approval - Original Invoice Submitted
A23: 20 | B23: 13-11-2025 and 30-12-2025 | C23: WO | E23: 45973 | F23: 0106 - 2025-26 | G23: Shiva Fabrication works | H23: Fabrication work | I23: 327123 | M23: =I23+L23 -> 327123 | N23: 40000 | Q23: =J23-P23 -> 0 | R23: 287123 | S23: =N23+O23+P23+Q23+R23 -> 327123 | T23: =M23-S23 -> 0 | U23: Submitted | V23: 23.12.2025 | W23: M-25-004 | X23: 327123 | AA23: Final Bill
A24: 21 | B24: 46056 | C24: WO | D24: AGN/WO/M-035/2025-26 | E24: 45659 | F24: 080 - 2025-26 | G24: Mounika Construction | H24: Civil Work for Compound wall | I24: 2812362.7 | L24: =I24*18% -> 506225.29 | M24: =I24+L24 -> 3318588 | R24: 3318588 | S24: =N24+O24+P24+Q24+R24 -> 3318588 | T24: =M24-S24 -> -0.0022 | U24: Submitted | V24: 03.02.2026 | W24: mou03/02/2026 | X24: 3318588 | AA24: Final Bill all original invoices submitted with client sign
A27: Grand Total | M27: =SUM(M4:M26) -> 23926473 | N27: =SUM(N4:N26) -> 8113601.2 | O27: =SUM(O4:O26) -> 438198.9 | P27: =SUM(P4:P26) -> 0 | Q27: =SUM(Q4:Q26) -> 0 | R27: =SUM(R4:R26) -> 12248060 | S27: =SUM(S4:S26) -> 20799860 | T27: =SUM(T4:T26) -> 3039292.5

Sheet Direct_Payments
A1: Invoice Tracker Direct Payments - 2024 to 2025
K2: Payment Details | R2: Invoice Status | V2: UTR Details
A3: S.No | B3: Date | C3: Budget No. | D3: Supplier | E3: Description | F3: Order Value | G3: Loading | H3: Freight | I3: Taxes | J3: Total Amount | K3: Advance 1 | L3: Advance 2 | M3: RA Bill 1 | N3: RA Bill 2 | O3: Final Bill | P3: Total Paid | Q3: Balance to pay | R3: Status | S3: Date | T3: Invoice No. | U3: Amount | V3: Date | W3: UTR No. | X3: Remarks
A4: 1 | B4: 45759 | C4: 004 - 2025-26 | D4: Beyond Home Solutions Pvt Ltd | E4: Supply of Ceiling Fans (M) | F4: 24600 | I4: =F4*18% -> 4428 | J4: =F4+I4 -> 29028 | K4: 29028 | P4: =K4+L4+M4+N4+O4 -> 29028 | Q4: =J4-P4 -> 0 | R4: Not Submitted | X4: 100% Advanec against client approval
A5: 2 | B5: 45776 | D5: Rao Enterprises | E5: Supply of Pillows | F5: 17416 | I5: =F5*18% -> 3134.88 | J5: =F5+I5 -> 20550.88 | O5: 20551 | P5: =K5+L5+M5+N5+O5 -> 20551 | Q5: =J5-P5 -> -0.12 | R5: Submitted | S5: 26.04.2025 | T5: 2 | U5: 20551 | X5: Original invoice submitted with client approval
A6: 3 | B6: 45790 | C6: Open | D6: Radha Krishna Granite & Tiles | E6: Supply of Thandoor Stone | F6: 24788.13 | I6: =F6*18% -> 4461.8634 | J6: =F6+I6 -> 29249.993 | O6: 29250 | P6: =K6+L6+M6+N6+O6 -> 29250 | Q6: =J6-P6 -> -0.0066 | R6: Submitted | S6: 02.05.2025 amd 05.05.2025 | T6: 5 and 6 | U6: =23726+5524 -> 29250 | X6: Original invoice submitted with client approval
A7: 4 | B7: 45790 | C7: Open | D7: Vijay Babu | E7: Supply of River sand | F7: 6332.5 | J7: =F7+I7 -> 6332.5 | O7: 6332.5 | P7: =K7+L7+M7+N7+O7 -> 6332.5 | Q7: =J7-P7 -> 0 | R7: Submitted | S7: 28.04.2025 | T7: 2 | U7: 6332.5 | X7: Original invoice submitted with client approval
A8: 5 | B8: 45790 | C8: Open | D8: SN Infra | E8: Supply of Cement | F8: 2640 | I8: =F8*28% -> 739.2 | J8: =F8+I8 -> 3379.2 | O8: 3380 | P8: =K8+L8+M8+N8+O8 -> 3380 | Q8: =J8-P8 -> -0.8 | R8: Submitted | S8: 30.04.2025 | T8: 265 | U8: 3380 | X8: Original invoice submitted with client approval
A9: 6 | B9: 45790 | C9: Open | D9: Raju Enterprises | E9: Supply of Stone Dust | F9: 9000 | J9: =F9+I9 -> 9000 | O9: 9000 | P9: =K9+L9+M9+N9+O9 -> 9000 | Q9: =J9-P9 -> 0 | R9: Submitted | S9: 04.05.2025 | T9: 74 | U9: 9000 | X9: Original invoice submitted with client approval
A10: 7 | B10: 45810 | C10: Open | D10: Radha Krishna Granite & Tiles | E10: Supply of Polished Granite | F10: 14691 | I10: =F10*18% -> 2644.38 | J10: =F10+I10 -> 17335.38 | O10: 17336 | P10: =K10+L10+M10+N10+O10 -> 17336 | Q10: =J10-P10 -> -0.62 | R10: Submitted | S10: 26.05.2025 | T10: 12 | U10: 17336 | X10: Original invoice submitted with client approval
A11: 8 | B11: 45840 | C11: Open | D11: Bhagya Laxmi Paint and Sanitary | E11: Supply of Plumbing Materials | F11: 38784.74 | I11: =F11*18% -> 6981.2532 | J11: =F11+I11 -> 45765.993 | O11: 45766 | P11: =K11+L11+M11+N11+O11 -> 45766 | Q11: =J11-P11 -> -0.0068 | R11: Submitted | S11: 21.06.2025 | T11: 1/130 | U11: 45766 | X11: Original invoice submitted with client approval
A12: 9 | B12: 45840 | C12: Open | D12: Bhagya Laxmi Paint and Sanitary | E12: Supply of Plumbing Materials | F12: 22152.54 | I12: =F12*18% -> 3987.4572 | J12: =F12+I12 -> 26139.997 | O12: 26140 | P12: =K12+L12+M12+N12+O12 -> 26140 | Q12: =J12-P12 -> -0.0028 | R12: Submitted | S12: 21.05.2025 | T12: 1/085 | U12: 26140 | X12: Original invoice submitted with client approval
A13: 10 | B13: 45840 | C13: Open | D13: Mayur Plywood & Electrical | E13: Supply of Hardware and Electrical Materials | F13: 22155.93 | I13: =F13*18% -> 3988.0674 | J13: =F13+I13 -> 26143.997 | O13: 26144 | P13: =K13+L13+M13+N13+O13 -> 26144 | Q13: =J13-P13 -> -0.0026 | R13: Submitted | S13: 23.06.2025 and 24.06.2025 | T13: 1974 and 1975 | U13: =4624+21520 -> 26144 | X13: Original invoice submitted with client approval
A14: 11 | B14: 45840 | C14: Open | D14: LGM Enterprises | E14: Supply of Light Fittings | F14: 5654.29 | I14: =F14*18% -> 1017.7722 | J14: =F14+I14 -> 6672.0622 | O14: 6672.9 | P14: =K14+L14+M14+N14+O14 -> 6672.9 | Q14: =J14-P14 -> -0.8378 | R14: Submitted | S14: 28.05.2025 | T14: 216 | U14: 6672.9 | X14: Original invoice submitted with client approval
A15: 12 | B15: 45840 | C15: Open | D15: SS Traders | E15: Supply of Light Fittings | F15: 14900 | I15: =F15*18% -> 2682 | J15: =F15+I15 -> 17582 | O15: 17582 | P15: =K15+L15+M15+N15+O15 -> 17582 | Q15: =J15-P15 -> 0 | R15: Submitted | S15: 23.06.2025 | T15: 25-26/0021 | U15: 17582 | X15: Original invoice submitted with client approval
A16: 13 | B16: 45840 | C16: Open | D16: Aslam Earth Movers | E16: Supply of JCB and Tractrs on Hire Basis | F16: 233500 | J16: =F16+I16 -> 233500 | O16: 233500 | P16: =K16+L16+M16+N16+O16 -> 233500 | Q16: =J16-P16 -> 0 | R16: Submitted | S16: 22.06.2025 | T16: 250 | U16: 233500 | X16: Original invoice submitted with client approval
A17: 14 | B17: 45887 | C17: Open | D17: Aslam Earth Movers | E17: Supply of JCB and Tractrs on Hire Basis | F17: 120700 | J17: =F17+I17 -> 120700 | O17: 120700 | P17: =K17+L17+M17+N17+O17 -> 120700 | Q17: =J17-P17 -> 0 | R17: Submitted | S17: 13.08.2025 | T17: 258 | U17: 120700 | X17: Original invoice submitted with client approval
A18: 15 | B18: 45887 | C18: Open | D18: SMR Earth Movers | E18: Supply of Murrum | F18: 25500 | J18: =F18+I18 -> 25500 | O18: 25500 | P18: =K18+L18+M18+N18+O18 -> 25500 | Q18: =J18-P18 -> 0 | R18: Submitted | S18: 10.08.2025 | T18: 3 | U18: 25500 | X18: Original invoice submitted with client approval
A19: 16 | B19: 45887 | C19: Open | D19: Gopal Earth Movers | E19: Supply of Murrum | F19: 147500 | J19: =F19+I19 -> 147500 | O19: 147500 | P19: =K19+L19+M19+N19+O19 -> 147500 | Q19: =J19-P19 -> 0 | R19: Submitted | S19: 07.08.2025 | T19: 56 | U19: 147500 | X19: Original invoice submitted with client approval
A20: 17 | B20: 45887 | C20: Open | D20: Saidulu Earth Movers | E20: Supply of Murrum | F20: 80100 | J20: =F20+I20 -> 80100 | O20: 80100 | P20: =K20+L20+M20+N20+O20 -> 80100 | Q20: =J20-P20 -> 0 | R20: Submitted | S20: 13.08.2025 | T20: 15 | U20: 80100 | X20: Original invoice submitted with client approval
A21: 18 | B21: 25.08.2025 | C21: 072 - 2025-26 | D21: Chabildas Manikdas & Bro | E21: Supply of Plumbing Materials | F21: 34054.23 | I21: =F21*18% -> 6129.7614 | J21: =F21+I21 -> 40183.991 | O21: 40184 | P21: =K21+L21+M21+N21+O21 -> 40184 | Q21: =J21-P21 -> -0.0086 | R21: Submitted | S21: 31.07.2025 | T21: JH482 | U21: 40184 | X21: Original invoice submitted with client approval
A22: 19 | B22: 45902 | C22: Open | D22: SMR Earth Movers | E22: Supply of Murrum | F22: 158600 | J22: =F22+I22 -> 158600 | O22: 158600 | P22: =K22+L22+M22+N22+O22 -> 158600 | Q22: =J22-P22 -> 0 | R22: Submitted | S22: 01.09.2025 | T22: 4 | U22: 158600 | X22: Original invoice submitted with client approval
A23: 20 | B23: 45902 | C23: Open | D23: R.K Ceramics | E23: Supply of Vetrified Tiles | F23: 25200 | I23: =F23*18% -> 4536 | J23: =F23+I23 -> 29736 | O23: 29736 | P23: =K23+L23+M23+N23+O23 -> 29736 | Q23: =J23-P23 -> 0 | R23: Submitted | S23: 28.08.2025 | T23: 59 | U23: 29736 | X23: Original invoice submitted with client approval
A24: 21 | B24: 45944 | C24: Open | D24: Aslam Earth Movers | E24: Supply of JCB and Tractrs on Hire Basis | F24: 107650 | J24: =F24+I24 -> 107650 | O24: =+J24 -> 107650 | P24: =K24+L24+M24+N24+O24 -> 107650 | Q24: =J24-P24 -> 0 | R24: Submitted | U24: 107650 | X24: Original invoice submitted with client approval
A25: 22 | B25: 45944 | C25: Open | D25: SMR Earth Movers | E25: Supply of JCB | F25: 23400 | J25: =F25+I25 -> 23400 | O25: =+J25 -> 23400 | P25: =K25+L25+M25+N25+O25 -> 23400 | Q25: =J25-P25 -> 0 | R25: Submitted | U25: 23400 | X25: Original invoice submitted with client approval
A26: 23 | B26: 45944 | C26: Open | D26: YP Stone | E26: Supply of Lime stone chips | F26: 29893.5 | J26: =F26+I26 -> 29893.5 | O26: =+J26 -> 29893.5 | P26: =K26+L26+M26+N26+O26 -> 29893.5 | Q26: =J26-P26 -> 0 | R26: Submitted | U26: 29893.5 | X26: Original invoice submitted with client approval
A27: 24 | B27: 45944 | C27: Open | D27: Royal Glass & UPVC works | E27: Supply of UPVC windows | F27: 11434 | J27: =F27+I27 -> 11434 | O27: =+J27 -> 11434 | P27: =K27+L27+M27+N27+O27 -> 11434 | Q27: =J27-P27 -> 0 | R27: Submitted | U27: 11434 | X27: Original invoice submitted with client approval
A28: 25 | B28: 45944 | C28: Open | D28: Sudhakar Dharavath | E28: Supply of labour | F28: 29250 | J28: =F28+I28 -> 29250 | O28: =+J28 -> 29250 | P28: =K28+L28+M28+N28+O28 -> 29250 | Q28: =J28-P28 -> 0 | R28: Submitted | U28: 29250 | X28: Original invoice submitted with client approval
A29: 26 | B29: 45944 | C29: Open | D29: Raju Enterprises | E29: Supply of dust | F29: 40690 | J29: =F29+I29 -> 40690 | O29: =+J29 -> 40690 | P29: =K29+L29+M29+N29+O29 -> 40690 | Q29: =J29-P29 -> 0 | R29: Submitted | U29: 40690 | X29: Original invoice submitted with client approval - Bank details not submitted
A30: 27 | B30: 45964 | C30: Open | D30: SMR Earth Movers | E30: Supply of JCB | F30: 54600 | J30: =F30+I30 -> 54600 | O30: =+J30 -> 54600 | P30: =K30+L30+M30+N30+O30 -> 54600 | Q30: =J30-P30 -> 0 | R30: Submitted | S30: 26.10.2025 | T30: 6 | U30: 54600 | X30: Original invoice submitted with client approval
A31: 28 | B31: 45964 | C31: Open | D31: Sudhakar Dharavath | E31: Supply of labour | F31: 11300 | J31: =F31+I31 -> 11300 | O31: =+J31 -> 11300 | P31: =K31+L31+M31+N31+O31 -> 11300 | Q31: =J31-P31 -> 0 | R31: Submitted | S31: 27.10.2025 | T31: 2 | U31: 11300 | X31: Original invoice submitted with client approval
A32: 29 | B32: 45964 | C32: Open | D32: Aslam Earth Movers | E32: Supply of JCB and Tractrs on Hire Basis | F32: 62750 | J32: =F32+I32 -> 62750 | O32: =+J32 -> 62750 | P32: =K32+L32+M32+N32+O32 -> 62750 | Q32: =J32-P32 -> 0 | R32: Submitted | S32: 27.10.2025 | T32: 260 | U32: 62750 | X32: Original invoice submitted with client approval
A33: 30 | B33: 45964 | C33: Open | D33: Bhagya Laxmi Paint and Sanitary | E33: Supply of Plumbing Materials | F33: 63681 | J33: =F33+I33 -> 63681 | O33: =+J33 -> 63681 | P33: =K33+L33+M33+N33+O33 -> 63681 | Q33: =J33-P33 -> 0 | R33: Submitted | S33: 24.09.25, 27.09.25, 26.09.25, 24.09.25 and 22.09/25 | T33: 1/304, 310,311, 314,318. 319 and 320 | U33: =3585+11520+890+4540+7870+32311+2965 -> 63681 | X33: Original invoice submitted with client approval
A34: 31 | B34: 45964 | C34: Open | D34: Mayur Plywood & Electrical | E34: Supply of Hardware and Electrical Materials | F34: 83417 | J34: =F34+I34 -> 83417 | O34: =+J34 -> 83417 | P34: =K34+L34+M34+N34+O34 -> 83417 | Q34: =J34-P34 -> 0 | R34: Submitted | S34: 5/9/25, 4/9/25, 1/9/25, 9/10/25 and 4/6/25 | T34: 1931, 2138, 2139, 2147, 2148, 2149 and 2221 | U34: =26539+10953+17812+2952+20840+2177+2144 -> 83417 | X34: Original invoice submitted with client approval
A35: 32 | B35: 46021 | C35: Open | D35: Aslam Earth Movers | E35: Supply of JCB and Tractrs on Hire Basis | F35: 90000 | J35: =F35+I35 -> 90000 | O35: =+J35 -> 90000 | P35: =K35+L35+M35+N35+O35 -> 90000 | Q35: =J35-P35 -> 0 | R35: Submitted | S35: 27.12.2025 | T35: M-25-002 | U35: 90000 | X35: Original invoice submitted with client approval
A36: 33 | B36: 46021 | C36: Open | D36: Sudhakar Dharavath | E36: Supply of labour | F36: 16190 | J36: =F36+I36 -> 16190 | O36: =+J36 -> 16190 | P36: =K36+L36+M36+N36+O36 -> 16190 | Q36: =J36-P36 -> 0 | R36: Submitted | S36: 27.12.2025 | T36: M-25-005 | U36: 16190 | X36: Original invoice submitted with client approval
A37: 34 | B37: 46021 | C37: Open | D37: Raju Enterprises | E37: Supply of dust and JCB and Tractrs on Hire Basis | F37: 156892 | J37: =F37+I37 -> 156892 | O37: =+J37 -> 156892 | P37: =K37+L37+M37+N37+O37 -> 156892 | Q37: =J37-P37 -> 0 | R37: Submitted | S37: 27.12.2025 | T37: M-25-003 | U37: 156892 | X37: Original invoice submitted with client approval - Bank details not submitted
A38: 35 | B38: 46021 | C38: Open | D38: Vijay Babu | E38: Supply of River sand | F38: 10204 | J38: =F38+I38 -> 10204 | O38: =+J38 -> 10204 | P38: =K38+L38+M38+N38+O38 -> 10204 | Q38: =J38-P38 -> 0 | R38: Submitted | S38: 27.12.2025 | T38: 15 | U38: 10204 | X38: Original invoice submitted with client approval
A39: 36 | B39: 46021 | C39: Open | D39: SMR Earth Movers | E39: Supply of Murrum | F39: 301600 | J39: =F39+I39 -> 301600 | O39: =+J39 -> 301600 | P39: =K39+L39+M39+N39+O39 -> 301600 | Q39: =J39-P39 -> 0 | R39: Submitted | S39: 27.12.2025 | T39: M-25-004 | U39: 301600 | X39: Original invoice submitted with client approval
A40: 37 | B40: 46071 | C40: Open | D40: Khaja Moin | E40: Supply of Murrum | F40: 114400 | J40: =F40+I40 -> 114400 | O40: =+J40 -> 114400 | P40: =K40+L40+M40+N40+O40 -> 114400 | Q40: =J40-P40 -> 0 | R40: Submitted | S40: 12.02.2026 | T40: SMR-26-005 | U40: 114400 | X40: Original invoice submitted with client approval
...
